Workbook
Name Modalidad: #REF!
Name Modalidad: #REF!
Name Modalidad: #REF!
Name Modalidad: '[1]Plan de pagos'!$R$13:$R$14
Name Modalidad: #REF!
Name Modalidad: 'Plan de pagos'!$R$13:$R$14

Sheet Simulador
A3: Plan de pagos: Carta de bienvenida
B5: Cuota | C5: Fecha de vencimiento | F5: Saldo capital | I5: Abono capital | K5: Intereses | L5: Vida Deudores | M5: Fianza | N5: Cuota | O5: TOTAL
B6: 0 | F6: {=+'Plan de pagos'!F18:H18} -> 480000 | G6: 0 | H6: 0
B7: =+'Plan de pagos'!B19 -> 1 | C7: =+'Plan de pagos'!C19 -> 11 | D7: =+'Plan de pagos'!D19 -> Ago | E7: =+'Plan de pagos'!E19 -> 2026 | F7: {=+'Plan de pagos'!F19:H19} -> 242530.04 | G7: 0 | H7: 0 | I7: {=+'Plan de pagos'!J19:K19} -> 237469.96 | J7: 0 | K7: =+'Plan de pagos'!L19 -> 10227.966 | L7: =+'Plan de pagos'!M19 -> 912 | M7: =+'Plan de pagos'!N19 -> 56248.92 | N7: =+'Plan de pagos'!O19 -> 247697.93 | O7: =+'Plan de pagos'!P19 -> 304858.85
B8: =+'Plan de pagos'!B20 -> 2 | C8: =+'Plan de pagos'!C20 -> 11 | D8: =+'Plan de pagos'!D20 -> Sep | E8: =+'Plan de pagos'!E20 -> 2026 | F8: {=+'Plan de pagos'!F20:H20} -> 2.910383e-11 | G8: 0 | H8: 0 | I8: {=+'Plan de pagos'!J20:K20} -> 242530.04 | J8: 0 | K8: =+'Plan de pagos'!L20 -> 5167.8936 | L8: =+'Plan de pagos'!M20 -> 912 | M8: =+'Plan de pagos'!N20 -> 56248.92 | N8: =+'Plan de pagos'!O20 -> 247697.93 | O8: =+'Plan de pagos'!P20 -> 304858.85
I9: {=+'Plan de pagos'!J21:K21} -> 480000 | J9: 0 | K9: =+'Plan de pagos'!L21 -> 15395.859 | L9: =+'Plan de pagos'!M21 -> 1824 | M9: =+'Plan de pagos'!N21 -> 112497.84 | N9: =+'Plan de pagos'!O21 -> 495395.86 | O9: =+'Plan de pagos'!P21 -> 609717.7
A13: Simulador:
A15: Valor solicitado | B15: =+'Plan de pagos'!P14 -> 450000
A16: Interés | B16: =+K9 -> 15395.859
A17: Seguro vida | B17: =+L9 -> 1824
A18: Fianza + IVA | B18: =+M9 -> 112497.84
A19: Tecnología + IVA | B19: =(+B15*3%)+7800 -> 21300
A20: Administración | B20: 30000
A21: Descuento (por inclusión financiera) | B21: =-B19 -> -21300
A22: Total a pagar | B22: =SUM(B15:B21) -> 609717.7

Sheet Plan de pagos
B2: TABLA DE AMORTIZACION DE CREDITOS CON CUOTAS FIJAS
B3: FINAMIGO
B5: DIGITE LA INFORMACIÓN | I5: CONVERSIÓN DE TASAS | L5: Solicitante: | M5: BELTRAN GAITAN KATHERINE LORENA | P5: FIANZA | XEV5: Libre Destino
B6: Valor del Crédito | F6: =+P14+30000 -> 480000 | I6: Efectiva Anual: | J6: 0.2879 | L6: Cédula: | M6: 1104701529 | P6: Modalidad | XEV6: Bajo Monto
B7: Tasa (mensual): | F7: =+J7 -> 0.021308262 | I7: EMV: | J7: =((J6+1)^(0.0833333333333333))-1 -> 0.021308262 | L7: Destino Crédito: | M7: Capital de trabajo | P7: Mensual | XEV7: Libranza
B8: Tiempo (meses): | F8: 2 | I8: ETV: | J8: =+((1+J7)^3)-1 -> 0.065296587 | L8: Entidad Trabajo: | M8: Eficacia | P8: Nivel de Riesgo
B9: Fechas pago del crédito | F9: 11 | G9: 7 | H9: 2026 | I9: ETA: | J9: =+J8/(1+J8) -> 0.06129428 | L9: Cargo: | M9: Elite | P9: 4
F10: Día | G10: Mes | H10: Año | I10: Nom Anual | J10: =+F7*12 -> 0.25569915 | L10: Linea de crédito | M10: Finamigo | P10: =+(P14*10.504%)*1.19 -> 56248.92
B13: TABLA DE AMORTIZACION CUOTA FIJA | L13: MONTO DEL CREDITO | N13: Solicitado | P13: 600000
N14: Aprobado | P14: 450000
B17: Cuota | C17: Fecha de vencimiento | F17: Saldo capital | J17: Abono capital | L17: Intereses | M17: Vida Deudores | N17: Fianza | O17: Cuota | P17: TOTAL
B18: 0 | C18: =F9 -> 11 | D18: =IF($G$9=1,"Ene",IF($G$9=2,"Feb",IF($G$9=3,"Mar",IF($G$9=4,"Abr",IF($G$9=5,"May",IF($G$9=6,"Jun",IF($G$9=7,"Jul",IF($G$9=8,"Ago",IF($G$9=9,"Sep",IF($G$9=10,"Oct",IF($G$9=11,"Nov","Dic"))))))))))) -> Jul | E18: =H9 -> 2026 | F18: =F6 -> 480000
B19: =+IF(P19>1,B18+1,"-") -> 1 | C19: =IF(J19>0,$C$18,"-") -> 11 | D19: =IF(C19="-","-",(IF($D18="Ene","Feb",IF($D18="Feb","Mar",IF($D18="Mar","Abr",IF($D18="Abr","May",IF($D18="May","Jun",IF($D18="Jun","Jul",IF($D18="Jul","Ago",IF($D18="Ago","Sep",IF($D18="Sep","Oct",IF($D18="Oct","Nov",IF($D18="Nov","Dic","Ene"))))))))))))) -> Ago | E19: =IF(C19="-","-",+IF($D18="Ene",E18,IF($D18="Feb",E18,IF($D18="Mar",E18,IF($D18="Abr",E18,IF($D18="May",E18,IF($D18="Jun",E18,IF($D18="Jul",E18,IF($D18="Ago",E18,IF($D18="Sep",E18,IF($D18="Oct",E18,IF($D18="Nov",E18,(E18+1))))))))))))) -> 2026 | F19: =+(F18-J19) -> 242530.04 | J19: =+($O$19-$L$19) -> 237469.96 | L19: =+(F18*$F$7) -> 10227.966 | M19: =IF(J19>0,((+$F$6*1.9)/1000),0) -> 912 | N19: =IF(J19>0,$P$10,0) -> 56248.92 | O19: =+(-PMT($F$7,$F$8,$F$6,0,0)) -> 247697.93 | P19: =O19+M19+N19 -> 304858.85
B20: =+IF(P20>1,B19+1,"-") -> 2 | C20: =IF(J20>0,$C$18,"-") -> 11 | D20: =IF(C20="-","-",(IF($D19="Ene","Feb",IF($D19="Feb","Mar",IF($D19="Mar","Abr",IF($D19="Abr","May",IF($D19="May","Jun",IF($D19="Jun","Jul",IF($D19="Jul","Ago",IF($D19="Ago","Sep",IF($D19="Sep","Oct",IF($D19="Oct","Nov",IF($D19="Nov","Dic","Ene"))))))))))))) -> Sep | E20: =IF(C20="-","-",+IF($D19="Ene",E19,IF($D19="Feb",E19,IF($D19="Mar",E19,IF($D19="Abr",E19,IF($D19="May",E19,IF($D19="Jun",E19,IF($D19="Jul",E19,IF($D19="Ago",E19,IF($D19="Sep",E19,IF($D19="Oct",E19,IF($D19="Nov",E19,(E19+1))))))))))))) -> 2026 | F20: =IF(F8<=1,0,+F19-J20) -> 2.910383e-11 | J20: =+IF(F8<=1,0,($O$19-$L$20)) -> 242530.04 | L20: =+(F19*$F$7) -> 5167.8936 | M20: =IF(J20>0,((+$F$6*1.9)/1000),0) -> 912 | N20: =IF(J20>0,$P$10,0) -> 56248.92 | O20: =IF(F8=1,0,(-PMT($F$7,$F$8,$F$6,0,0))) -> 247697.93 | P20: =O20+M20+N20 -> 304858.85
J21: =+J20+J19 -> 480000 | L21: =+L20+L19 -> 15395.859 | M21: =+M20+M19 -> 1824 | N21: =+N20+N19 -> 112497.84 | O21: =+O20+O19 -> 495395.86 | P21: =+P20+P19 -> 609717.7

Sheet Flujo Empleado
B1: ANALISIS FINANCIERO PAGO DE CREDITOS
B2: Asalariado / Independiente
B4: Solicitante | C4: {=+'Plan de pagos'!M5:N5} -> BELTRAN GAITAN KATHERINE LORENA | D4: 0
B5: C.C No. | C5: {=+'Plan de pagos'!M6:N6} -> 1104701529 | D5: 0
B7: Estado de Ingresos y Resultados | D7: Valor | E7: % Partc
C8: Ingreso Reportado cliente | D8: =8000000+1500000 -> 9500000
C9: QUANTO ingreso medio | D9: 9437377
B10: Entradas Mensuales | C10: Ingresos Brutos (salario, pensión, contratos) | D10: =+MIN(D8,D9) -> 9437377 | E10: =+D10/D15 -> 1
C11: Comisiones, Rodamiento, Bonificaciones | D11: 0 | E11: =+D11/D15 -> 0
C12: Arriendos | D12: 0 | E12: =+D12/D15 -> 0
C13: Rendimientos Financieros | D13: 0 | E13: =+D13/D15 -> 0
C14: Otros ingresos | D14: 0 | E14: =+D14/D15 -> 0
C15: TOTAL INGRESOS | D15: =SUM(D10:D14) -> 9437377 | E15: =SUM(E10:E14) -> 1
C16: Descuentos de Ley | D16: =+D15*0.08 -> 754990.16 | E16: =+D16/D15 -> 0.08
C17: TOTAL INGRESOS NETOS | D17: =D15-D16 -> 8682386.8 | E17: =+D17/D15 -> 0.92
B19: Salidas Mensuales | C19: Gastos de sostenimiento | D19: =+D17*35% -> 3038835.4 | E19: =+D19/D26 -> 0.13469516
C20: Arrendamientos | D20: 0 | E20: =+D20/D26 -> 0
C21: Manutención hijos (10% salario c/u) | E21: =+D21/D26 -> 0
C22: Cuotas Créditos | D22: 19522000 | E22: =+D22/D26 -> 0.86530484
C23: Cuotas tarjetas | D23: 0 | E23: =+D23/D26 -> 0
C24: Cuotas deudas particulares | D24: 0 | E24: =+D24/D26 -> 0
C25: Otros Gastos | D25: 0 | E25: =+D25/D26 -> 0
C26: TOTAL GASTOS | D26: =SUM(D19:D25) -> 22560835 | E26: =SUM(E19:E25) -> 1
B28: Balance General | D28: Valor | E28: % Partc
B29: Activos | C29: Bienes Inmuebles | D29: 0 | E29: =+D29/D34 -> #DIV/0!
C30: Vehículos | D30: 0 | E30: =+D30/D34 -> #DIV/0!
C31: Muebles y enseres | E31: =+D31/D34 -> #DIV/0!
C32: Maquinaria y Equipo | D32: 0 | E32: =+D32/D34 -> #DIV/0!
C33: Otros | D33: 0 | E33: =+D33/D34 -> #DIV/0!
C34: TOTAL ACTIVOS | D34: =SUM(D29:D33) -> 0 | E34: =SUM(E29:E33) -> #DIV/0!
B35: Pasivos | C35: Deudas con Bancos | E35: =+D35/D39 -> #DIV/0!
C36: Deudas Particulares | D36: 0 | E36: =+D36/D39 -> #DIV/0!
C37: Deudas Compra de cartera Finalco y Bancos | D37: 0 | E37: N/A
C38: Deudas Proveedores | D38: 0 | E38: =+D38/D39 -> #DIV/0!
C39: TOTAL PASIVOS | D39: =+D35+D36+D38 -> 0 | E39: =SUM(E35:E38) -> #DIV/0!
B41: Patrimonio | C41: Vr. Patrimonio Neto | E41: =+D34-D39 -> 0
B43: Indicadores de análisis
C44: Monto del crédito Solicitado | E44: =+'Plan de pagos'!P13 -> 600000
B45: Información | C45: Monto del crédito Aprobado | E45: =+'Plan de pagos'!P14 -> 450000
B46: del crédito | C46: Plazo | E46: {=+'Plan de pagos'!F8:H8} -> 2 | F46: 0 | G46: 0
...

Sheet Analisis
B2: HOJA DE ANALISIS
B4: Nombre Analista | C4: Dayana Garibello
B6: Solicitante | C6: =+'Flujo Empleado'!C4 -> BELTRAN GAITAN KATHERINE LORENA | D6: Entidad Trabajo | E6: =+'Plan de pagos'!M8 -> Eficacia
B7: Doc de Identidad | C7: =+'Flujo Empleado'!C5 -> 1104701529 | D7: Cargo | E7: =+'Plan de pagos'!M9 -> Elite
B8: Destino del crédito | C8: =+'Plan de pagos'!M7 -> Capital de trabajo | D8: Linea | E8: =+'Plan de pagos'!M10 -> Finamigo
B10: Parametros aprobación o rechazo
B11: Detalle | C11: Valor | D11: Decisión de Préstamo
B12: Puntaje Begini | C12: 0 | D12: =IF(C12=0,"No contesto", IF(C12=1,"Riesgo más alto", IF(C12=2,"Riesgo muy alto", IF(C12=3,"Riesgo alto", IF(C12=4,"Riesgo medio", IF(C12=5,"Riesgo bajo", IF(C12=6,"Riesgo muy bajo", IF(C12=7,"Riesgo más bajo", IF(C12=8,"No terminó",""))))))))) -> No contesto
B13: Puntaje en centrales de riesgo | C13: 697 | D13: =+IF(C13<500,"Rechazar",(IF(C13<700,"Estudio",IF(C13>=700,"Prestar",0)))) -> Estudio
B14: Quanto medio | C14: =+'Flujo Empleado'!D10 -> 9437377 | D14: =+IF(C14>=H14,"Prestar","Rechazado") -> Prestar | H14: 1000000
B15: Cuota nueva + total gastos | C15: =+'Plan de pagos'!P19+'Flujo Empleado'!D26 -> 22865694 | D15: =+IF(C15<=C14,"Prestar","Rechazado") -> Rechazado
B16: Capacidad de pago | C16: =+C14-C15 -> -13428317 | D16: =+IF(C16<=0,"Rechazado","Prestar") -> Rechazado
B17: Marcación de si cliente (empleado) es cotizante (Adress) | C17: SI | D17: =+IF(C17="SI","Prestar","Rechazado") -> Prestar
G18: Solicita un monto menor o igual a $ | H18: =IF(+MAX(#REF!)=0,"Rechazado", (+CONCATENATE(G18,+MAX(#REF!)))) -> #REF!
H19: SI
B20: Detalle | C20: Valor | D20: Concepto de la solicitud - Ejecutivo de Cuenta | H20: NO
B21: Monto Solicitado | C21: =+'Plan de pagos'!P13 -> 600000 | D21: Tipo crédito:Nuevo Adres: Cotizante Validación de identidad Email: ABR 2014 Dirección:NO Tel Cel: MAR 2021 Cuenta:DIC 2021 Bancolombia Lote Begini: Novedad: Propiedades:Automovil Placa Icp242 Nota:
B22: Monto Aprobado | C22: =+'Plan de pagos'!P14 -> 450000
B23: Compra de cartera
B24: Descuentos
B25: Neto a Desembolsar | C25: =+C22-C23-C24 -> 450000
B27: Concepto de la solicitud - Comité de Crédito
B28: VoBO 450 COND 6 TDC AL 100%, ENDEUDADA, INDICARLE LA IMPORTANCIA DE PAGAR AL DIA.Actualizar direccion con cliente y HC
C34: Fecha: | E34: Firmas

Sheet Guion
B2: GUIÓN PRE-APROBADO FINAMIGO
B4: Saludo | C4: Buen día sr(a)________________, Habla con __________ del aréa de crédito de Finalco SAS. ¿Como se encuentra el día de hoy? Rta. Positiva: Me alegra Rta negativa: Entiendo El motivo de mi llamada, se debe a que ud. Solicito un préstamo Finamigo, el cual se encuentra en estado pre-aprobado
B6: Preguntas Reto | C6: , por lo que requerimos realizar unas preguntas de seguridad, para validar su identidad. Quisiera conocer si ud. dispone de unos minutos para atender la llamada, de salir positivas las respuestas procedemos a brindar las condiciones del crédito y firmar el pagaré digital.
C7: Rta. Positiva: De acuerdo (realizar Preguntas reto)
C8: Rta negativa: Entiendo, en que horario puedo llamarlo nuevamente. Entonces me contactare en ese horario. Recuerde que hablo con ____________ de Finalco SAS. Que tenga buen resto de día.
B10: condiciones de crédito en caso de que cambie el valor de la solicitud | C10: Cliente pasa el filtro, debe responder 3/4: | E10: Cliente NO pasa el filtro, debe responder 3/4:
C11: Perfecto sr(a)________ las respuestas fueron correctas, por lo cual procedo a indicarle las condiciones del crédito: Monto:________ Plazo:_________ Valor cuota:______________ Fecha de pago:___________ | E11: Sr(a)________, lamento informarle que fallamos en las respuestas de seguridad, por lo cual el sistema rechaza automaticamente su solicitud de crédito. Recuerde que hablo con ____________ de Finalco SAS. Que tenga buen resto de día.
C12: ¿Tiene alguna duda con la información brindada?
B14: Firma Pagaré | C14: Rta. Positiva: Le confirmo el proceso para firmar el pagaré y aprobar la solicitud. Rta negativa: Resolver inquietud
C16: A su correo electronico le va a llegar en unos minutos un email para la firma de pagaré digital. A su whatsapp le voy a enviar el link del video donde explica como hacer el proceso, el cual es muy sencillo. Inmediatamente quede firmado el documento, a ud. Le llega una copia a su correo. | E16: https://finalco.com.co/firma_pagare/
B17: Confirmar la cuenta bancaria… Preguntar si tiene nequi o Bancolombia La cuenta si o si debe estar a nombre del cliente
B18: Despedida | C18: Recuerde que una vez quede aprobado el préstamo le llegará un correo informandolo y cuando se realice el desembolso, le llegara una carta de bienvenida con la información del crédito y los canales de pago.
C19: Le recuerdo tambien que este crédito es diferente al actual por lo que son dos cuotas apartes
C20: Muchas gracias por atender mi llamada, recuerde que hablo con ____________ de Finalco SAS. Que tenga buen resto de día.

Sheet Preguntas_Reto
Q1: SI
B2: Preguntas reto | Q2: NO
B3: Consideraciones, siempre se debe preguntar: - Fecha de expedición de CC -3 preguntas de datacrédito (minimo una afirmativa y una negativa)
B4: 0. Me puede indicar por favor la fecha y lugar de expedición de su CC (cliente debe responder rapidamente) | G4: 4. Me puede indicar por favor si ud. Tiene una cuenta activa de ahorros con el banco (Validar en datacrédito un banco con el que SI tenga producto). Rta Afirmativa
B7: 1. Me puede indicar por favor si ud. Tiene una cuenta activa de ______ (crédito o TDC) con el banco (Validar en datacrédito un banco con el que SI tenga producto). Rta Afirmativa | G7: 5. Me puede indicar por favor si ud. Tiene una cuenta activa con operador movil____ (validar en datacrédito con el que SI tenga producto). Rta afirmativa
B10: 2. Me puede indicar por favor si ud. Tiene una cuenta activa de______(crédito o TDC) con el banco (Validar en datacrédito un banco con el que NO tenga producto). Rta negativa | G10: 6. Me puede indicar por favor si ud. Tiene una cuenta activa con operador movil____ (validar en datacrédito con el que NO tenga producto). Rta negativa
B14: 3. Me puede indicar por favor si ud. Tiene una cuenta activa de ahorros con el banco (Validar en datacrédito un banco con el que NO tenga producto). Rta negativa

Sheet Referenciación
B2: FORMATO DE REFERENCIACION
B4: Asesor
B6: Observaciones del Crédito:
B9: Certificación Laboral
B11: Nombre: | E11: Teléfono
B13: Cargo: | E13: Observaciones:
B15: Referencia 2.
B17: Nombre | E17: Teléfono
P18: propia
B19: Parentesco | P19: Arrendada
P20: Familiar
B21: Hace cuanto conoce al señor (a)
A22: En qué lugar vive:
F23: hace cuánto tiempo:
B25: Cuál es la actividad principal: | G25: Empresa (si es empleado)
B27: Cuantos hijos tiene | G27: de que edades
B29: Vive en casa:
B31: Qué referencia me podría dar del señor (a):
B33: Referencia 1.
B35: Nombre | E35: Teléfono
B37: Parentesco
B39: Hace cuanto conoce al señor (a)
A40: En qué lugar vive:
F41: hace cuánto tiempo:
B43: Cuál es la actividad principal: | G43: Empresa (si es empleado)
B45: Cuantos hijos tiene | G45: de que edades
B47: Vive en casa:
B49: Qué referencia me podría dar del señor (a):

Sheet Fotos
B2: Registro fotografico de Selfie
B4: Hipervinculo
B21: Cedula Cara 1
B40: Cedula Cara 2

Sheet Preguntas reto
B2: GUION PREGUNTAS RETO FINAMIGO
B4: SALUDO | C4: Buen día sr(a)________________, Habla con __________ del área de crédito de Finalco SAS. ¿Como se encuentra el día de hoy? Rta. Positiva: Me alegra Rta negativa: Entiendo
C6: El motivo de mi llamada se debe a que usted solicito un préstamo Finamigo, y para el desembolso se hace necesario validar su identidad.
C8: Le informamos que este procedimiento no tomara mucho tiempo y será muy breve.
C9: Le recomendamos igualmente preste atención a las preguntas y a las respuestas ya que de este proceso depende la aprobación final del crédito. En caso de que las preguntas quede mal contestadas, el área de gestión de riesgo se comunicara posteriormente con usted.
C12: 1. Me puede confirmar la fecha de expedición de su documento.
C13: Rta: debe validar directamente en la cedula
C14: 2. ¿Con que banco usted tiene cuenta de ahorro?
B15: PREGUNTAS | C15: A.) Caja social.
C16: B.) Bogota.
C17: C.) Pichincha.
C18: D.) Ninguna de las anteriores.
C19: Rta:
C20: 3. ¿Con que banco tiene usted tarjeta de credito?
C21: A.) Colpatria.
C22: B.) Juriscop.
C23: C.) Bancolombia.
C24: D.) Ninguna de las anteriores.
C25: Rta:
C26: 4.) Usted conoce o ha tenido contacto con alguna de las siguientes direcciones.?
C27: Direccion 1:
... C30: Nota Finalco:
B34: Video descarga NEQUI cetificado | C34: https://www.youtube.com/watch?v=aYt_zxMKKwM&t=5s
B35: Video descarga Daviplata cetificado | C35: https://www.youtube.com/watch?v=rIN4zjCPmq8

Sheet ListaDepegable
C1: 0 | D1: No contesto
B2: Highest Risk | C2: 1 | D2: Riesgo mas alto
B3: Very High Risk | C3: 2 | D3: Riesgo muy alto
B4: High Risk | C4: 3 | D4: Riesgo alto
B5: Medium Risk | C5: 4 | D5: Riesgo Medio
B6: Low Risk | C6: 5 | D6: Riesgo Bajo
B7: Very Low Risk | C7: 6 | D7: Riesgo muy bajo
B8: Lowest Risk | C8: 7 | D8: Riesgo mas bajo
C9: 8 | D9: No termino
A12: Tutorial begini | B12: Z:\500AdmFinanciera\520Administrativa\520.11Grupos_Interes\Sistemas_informacion\Begini
A14: Nombre archivo | B14: Alcance_Entendimiento_Proyecto

Sheet Evidencia Fotografica
B2: EVIDENCIA FOTOGRAFICA
B4: Solicitante | C4: =+'Plan de pagos'!M5 -> BELTRAN GAITAN KATHERINE LORENA
B5: Doc de Identidad | C5: =+'Plan de pagos'!M6 -> 1104701529
B6: Destino del crédito | C6: =+'Plan de pagos'!M7 -> Capital de trabajo
B8: EVIDENCIA FOTOGRAFICA DEL SITIO DE TRABAJO Y DEL CLIENTE
B52: MAPA DE UBICACIÓN DEL CLIENTE
