Workbook
Name LST_ADRES: Listas!$A$121:$A$124
Name LST_APETITO: Listas!$A$104:$A$108
Name LST_ARRAIGO: Listas!$A$90:$A$93
Name LST_BANCARIZACION: Listas!$A$95:$A$97
Name LST_CALIFICACION: Listas!$A$55:$A$58
Name LST_CARGA: Listas!$A$17:$A$20
Name LST_CARGA_TOTAL: Listas!$A$75:$A$78
Name LST_CIERRES: Listas!$A$33:$A$37
Name LST_COHERENCIA: Listas!$A$80:$A$83
Name LST_COMP_6M: Listas!$A$22:$A$26
Name LST_DISPONIBLE: Listas!$A$65:$A$68
Name LST_ESTADO_ACTUAL: Listas!$A$28:$A$31
Name LST_EXPERIENCIA: Listas!$A$60:$A$63
Name LST_FORMALIDAD: Listas!$A$100:$A$102
Name LST_HOLGURA: Listas!$A$7:$A$10
Name LST_IDENTIDAD: Listas!$A$85:$A$88
Name LST_MORA_12M: Listas!$A$44:$A$48
Name LST_MORA_HOY: Listas!$A$12:$A$15
Name LST_PESO_CUOTA: Listas!$A$70:$A$73
Name LST_PUNTUALIDAD: Listas!$A$39:$A$42
Name LST_TDC: Listas!$A$129:$A$133
Name LST_TENDENCIA: Listas!$A$50:$A$53
Name LST_USO_CUPO: Listas!$A$2:$A$5
Name Modalidad: '[2]Plan de pagos'!$R$13:$R$14
Name Modalidad: #REF!
Name Modalidad: '[1]Plan de pagos'!$R$13:$R$14
Name Modalidad: #REF!
Name Modalidad: 'Plan de pagos'!#REF!

Sheet Plan de pagos
B2: TABLA DE AMORTIZACION DE CREDITOS CON CUOTAS FIJAS
B3: FINAMIGO
B5: DIGITE LA INFORMACIÓN | I5: CONVERSIÓN DE TASAS | L5: Solicitante: | P5: FIANZA | XER5: Libre Destino
B6: Valor del Crédito | F6: =+P14+30000 -> 30000 | I6: Efectiva Anual: | J6: 0.2426 | L6: Cédula: | P6: Modalidad | XER6: Bajo Monto
B7: Tasa (mensual): | F7: =+J7 -> 0.018265303 | I7: EMV: | J7: =((J6+1)^(0.0833333333333333))-1 -> 0.018265303 | L7: Destino Crédito: | P7: Mensual | XER7: Libranza
B8: Tiempo (meses): | F8: 2 | I8: ETV: | J8: =+((1+J7)^3)-1 -> 0.055802868 | L8: Entidad Trabajo: | P8: Nivel de Riesgo
B9: Fechas pago del crédito | F9: 14 | G9: 1 | H9: 2026 | I9: ETA: | J9: =+J8/(1+J8) -> 0.052853491 | L9: Cargo: | P9: 4
F10: Día | G10: Mes | H10: Año | I10: Nom Anual | J10: =+F7*12 -> 0.21918364 | L10: Linea de crédito | P10: =+(P14*10.504%)*1.19 -> 0
B13: TABLA DE AMORTIZACION CUOTA FIJA | L13: MONTO DEL CREDITO | N13: Solicitado
N14: Aprobado
B17: Cuota | C17: Fecha de vencimiento | F17: Saldo capital | J17: Abono capital | L17: Intereses | M17: Vida Deudores | N17: Fianza | O17: Cuota | P17: TOTAL
B18: 0 | C18: =F9 -> 14 | D18: =IF($G$9=1,"Ene",IF($G$9=2,"Feb",IF($G$9=3,"Mar",IF($G$9=4,"Abr",IF($G$9=5,"May",IF($G$9=6,"Jun",IF($G$9=7,"Jul",IF($G$9=8,"Ago",IF($G$9=9,"Sep",IF($G$9=10,"Oct",IF($G$9=11,"Nov","Dic"))))))))))) -> Ene | E18: =H9 -> 2026 | F18: =F6 -> 30000
B19: =+IF(P19>1,B18+1,"-") -> 1 | C19: =IF(J19>0,$C$18,"-") -> 14 | D19: =IF(C19="-","-",(IF($D18="Ene","Feb",IF($D18="Feb","Mar",IF($D18="Mar","Abr",IF($D18="Abr","May",IF($D18="May","Jun",IF($D18="Jun","Jul",IF($D18="Jul","Ago",IF($D18="Ago","Sep",IF($D18="Sep","Oct",IF($D18="Oct","Nov",IF($D18="Nov","Dic","Ene"))))))))))))) -> Feb | E19: =IF(C19="-","-",+IF($D18="Ene",E18,IF($D18="Feb",E18,IF($D18="Mar",E18,IF($D18="Abr",E18,IF($D18="May",E18,IF($D18="Jun",E18,IF($D18="Jul",E18,IF($D18="Ago",E18,IF($D18="Sep",E18,IF($D18="Oct",E18,IF($D18="Nov",E18,(E18+1))))))))))))) -> 2026 | F19: =+(F18-J19) -> 15135.75 | J19: =+($O$19-$L$19) -> 14864.25 | L19: =+(F18*$F$7) -> 547.9591 | M19: =IF(J19>0,((+$F$6*1.9)/1000),0) -> 57 | N19: =IF(J19>0,$P$10,0) -> 0 | O19: =+(-PMT($F$7,$F$8,$F$6,0,0)) -> 15412.209 | P19: =O19+M19+N19 -> 15469.209
B20: =+IF(P20>1,B19+1,"-") -> 2 | C20: =IF(J20>0,$C$18,"-") -> 14 | D20: =IF(C20="-","-",(IF($D19="Ene","Feb",IF($D19="Feb","Mar",IF($D19="Mar","Abr",IF($D19="Abr","May",IF($D19="May","Jun",IF($D19="Jun","Jul",IF($D19="Jul","Ago",IF($D19="Ago","Sep",IF($D19="Sep","Oct",IF($D19="Oct","Nov",IF($D19="Nov","Dic","Ene"))))))))))))) -> Mar | E20: =IF(C20="-","-",+IF($D19="Ene",E19,IF($D19="Feb",E19,IF($D19="Mar",E19,IF($D19="Abr",E19,IF($D19="May",E19,IF($D19="Jun",E19,IF($D19="Jul",E19,IF($D19="Ago",E19,IF($D19="Sep",E19,IF($D19="Oct",E19,IF($D19="Nov",E19,(E19+1))))))))))))) -> 2026 | F20: =IF(F8<=1,0,+F19-J20) -> -1.8189894e-12 | J20: =+IF(F8<=1,0,($O$19-$L$20)) -> 15135.75 | L20: =+(F19*$F$7) -> 276.45907 | M20: =IF(J20>0,((+$F$6*1.9)/1000),0) -> 57 | N20: =IF(J20>0,$P$10,0) -> 0 | O20: =IF(F8=1,0,(-PMT($F$7,$F$8,$F$6,0,0))) -> 15412.209 | P20: =O20+M20+N20 -> 15469.209
J21: =+J20+J19 -> 30000 | L21: =+L20+L19 -> 824.41817 | M21: =+M20+M19 -> 114 | N21: =+N20+N19 -> 0 | O21: =+O20+O19 -> 30824.418 | P21: =+P20+P19 -> 30938.418

Sheet Captura información
B2: CAPTURA EXPERIAN · digite lo que ve en el PDF (PN + Preselecta) , otros documentos o sistemas de informacion
B3: AMARILLO = usted digita · GRIS = automatico. PRIMERO diligencie SOLO el PASO 1 (pre-filtro): si da NEGAR, registre la decision y NO diligencie el resto.
B5: PASO 1 · PRE-FILTRO RAPIDO DE NEGACION · PN pagina 1 + Preselecta pagina 1 · diligencie SOLO esto primero
C6: Tipo de credito (solicitud Finalco) | D6: Renovacion | F6: Solicitud interna / conocimiento del cliente
C7: Estado del Documento | D7: Vigente | F7: PN pag.1 > INFORMACION BASICA > Estado Documento
C8: Tipo de respuesta de la consulta (1/5/6/7) | D8: 0 | F8: PN ULTIMA pag. > Fin-consulta Tipo (una mirada rapida)
C9: Creditos Vigentes (Total Sectores) | D9: 0 | F9: PN pag.1 > RESUMEN > Creditos Vigentes > Total Sectores
C10: Creditos Cerrados (Total Sectores) | D10: 0 | F10: PN pag.1 > RESUMEN > Creditos Cerrados > Total Sectores
C11: ¿La experiencia es SOLO telco? (Financiero/Coop/Real todo en 0) | D11: Sin experiencia | F11: PN pag.1 > RESUMEN: columnas por sector
C12: -> Experiencia crediticia (automatico) | D12: =IF(H19="","(complete vigentes/cerrados)",IF(H19="SI","NINGUNA -> NEGAR",IF(H20="SI","SOLO TELCO -> Ruta Nuevo ($200K max)","Experiencia valida (vigente o cerrada)"))) -> NINGUNA -> NEGAR
C13: Saldo en Mora TOTAL hoy (PESOS) | D13: 0 | F13: PN pag.1 > Endeudamiento Actual TOTAL > Saldo en Mora (o Tendencia, mes mas reciente x1000)
C14: Peor mora ACTUAL (Total Moras Maximas, columna mas reciente: N/1/2/3/4/C/D) | D14: Sin dato | F14: PN pag.1 > Tendencia de endeudamiento > Total Moras Maximas, 1a columna
C15: Num. creditos con mora >= 60 dias (vigente) | D15: 0 | F15: PN pag.1 > Tendencia > Num creditos con mora >= 60, columna mas reciente
C16: ¿Cartera castigada o dudoso recaudo VIGENTE? (Solo telco = castigo unicamente en sector telcos) | D16: NO | F16: PN pag.1 > Endeudamiento Actual > Estado/Calf. Si el castigo esta unicamente en Sector Telcos elija "Solo telco" (tipico: saldo de celular o suplantacion; se analiza aparte, no niega)
C17: # de obligaciones EN MORA hoy | D17: 0 | F17: PN pag.1 > Endeudamiento Actual: cuente las filas con Saldo en Mora > 0
C18: Decision Preselecta | D18: Estudio | F18: Preselecta pag.1 > Decision (Aprobado/Rechazado)
C19: RESULTADO PRE-FILTRO | D19: =IF(OR(H19="SI",AND(D7<>"",D7<>"Vigente"),AND(D8<>"",N(D8)>=5),H21="SI",H22="SI"),"NEGAR DE INMEDIATO · NO diligencie el resto",IF(OR(D7="",D8="",D9="",D10="",D13="",D14="",D15="",D16="",D17=""),"(pendiente: complete todos los campos del pre-filtro)","CONTINUE · diligencie los Pasos 2 a 6")) -> NEGAR DE INMEDIATO · NO diligencie el resto | G19: sin experiencia? | H19: =IF(OR(D9="",D10=""),"",IF(OR(N(D9)+N(D10)=0,D11="Sin experiencia"),"SI","NO")) -> SI
C20: -> Motivos / notas | D20: =TRIM(IF(AND(D7<>"",D7<>"Vigente"),"· Documento no vigente. ","")&IF(AND(D8<>"",N(D8)>=5),"· Consulta tipo 5/6/7 no valida. ","")&IF(H19="SI","· Sin NINGUNA experiencia crediticia (ni cerrada ni telco). ","")&IF(H21="SI","· Castigada/dudoso vigente con saldo > "&TEXT(Reglas!$B$23,"$#,##0")&". ","")&IF(H22="SI","· Mora evidente superior (saldo > "&TEXT(Reglas!$B$23,"$#,##0")&" o 2+ obligaciones con mora 60+). ","")&IF(AND(D18="Rechazado",H19<>"SI",H21<>"SI",H22<>"SI"),"ALERTA: Preselecta dice Rechazado - verificar. ","")&IF(D18="Estudio","Nota: Preselecta en Estudio (sin decision automatica). ","")&IF(AND(OR(D16="SI",D14="C",D14="D"),H21="NO",H21<>""),"Nota: castigada/mora con saldo <= "&TEXT(Reglas!$B$23,"$#,##0")&" y demas obligaciones bien pagas -> continua. ","")&IF(D16="Solo telco","Nota: castigo SOLO telco (tipico saldo de celular o suplantacion) -> analizar aparte, no niega. ","")&IF(AND(H22="NO",H22<>"",D17<>"",N(D17)<=1,N(D13)>0),"Nota: mora unica con demas obligaciones al dia -> continua. ","")&IF(AND(H22="NO",D6="Renovacion",N(D13)>0,N(D13)<=Reglas!$B$23),"Nota: renovacion con mora <= "&TEXT(Reglas!$B$23,"$#,##0")&" -> continua. ","")&IF(H23="SI","-> MONTO MAXIMO SUGERIDO: "&TEXT(Reglas!$B$177,"$#,##0")&". ","")) -> · Sin NINGUNA experiencia crediticia (ni cerrada ni telco). Nota: Preselecta en Estudio (sin decision automatica). | G20: ruta nuevo (solo telco)? | H20: =IF(H19="","",IF(AND(H19="NO",D11="SI"),"SI","NO")) -> NO
G21: castigada niega? | H21: =IF(AND(D16="",D14=""),"",IF(AND(OR(D16="SI",D14="C",D14="D"),N(D13)>Reglas!$B$23),"SI","NO")) -> NO
G22: mora evidente niega? | H22: =IF(D13="","",IF(AND(OR(N(D13)>Reglas!$B$23,N(D15)>=2),NOT(OR(AND(D17<>"",N(D17)<=1),AND(D6="Renovacion",N(D13)<=Reglas!$B$23),AND(N(D13)<=Reglas!$B$23,OR(D14="N",D14="1",D14="2",D14="Sin dato"))))),"SI","NO")) -> NO
B23: PASO 2 · IDENTIFICACION (PN pag.1 arriba) · SOLO si el pre-filtro dice CONTINUE | G23: tope $250K? | H23: =IF(OR(H21="SI",H22="SI",D13=""),"",IF(AND(D16="Solo telco",N(D13)<=0,N(D15)=0),"NO",IF(OR(D16="SI",D16="Solo telco",D14="C",D14="D",N(D13)>0,N(D15)>0),"SI","NO"))) -> NO
C24: Fecha de nacimiento (DD/MM/AAAA) | F24: Digitarla desde la cedula
C25: -> Edad calculada (años)
C26: Tiene RUT? | F26: PN pag.1 > INFORMACION BASICA > Tiene RUT?
B28: PASO 3 · RESUMEN, ENDEUDAMIENTO Y TENDENCIA (PN pag.1)
C29: Año del credito mas antiguo (ej 2002) | F29: PN pag.1 > RESUMEN > Antiguedad desde
C30: -> Años de historial | D30: =IFERROR(YEAR(TODAY())-IF(ISNUMBER(D29),D29,YEAR(D29)),"") -> 126
C31: % Deuda TOTAL (Saldo/Cupo) | F31: PN pag.1 > Endeudamiento Actual TOTAL > % Deuda
C32: Valor Cuota TOTAL del reporte (PESOS) | F32: PN pag.1 > Endeudamiento Actual TOTAL > Valor Cuota (sin TDC)
C33: De esa cuota, ¿cuanto es de NANOCREDITOS? ($) | F33: PN pag.1 > Endeudamiento Actual: sumar cuotas de nanocreditos (<= $800K)
C34: De esa cuota, ¿cuanto es de Tarjetas de credito? ($) | F34: PN pag.1 > Endeudamiento Actual: sumar cuotas solo de TDC
C35: % promedio de uso de las TDC (Saldo/Cupo) | F35: PN pag.1 > Endeudamiento Actual: % Deuda solo de las TDC (promedio)
C36: Calificacion entidades (A/AB/C/DE) | F36: PN pag.1 > Endeudamiento Actual > columna Calf
C37: Consultas de ENTIDADES en 6 meses (EXCLUYA "CIUDADANO" y "CONSULTAS LOTE") | F37: PN pag.1 RESUMEN > Consultas 6m y pag.4 Historico: reste las consultas hechas por el mismo cliente (CIUDADANO) y las CONSULTAS LOTE de entidades
C38: Peor mora maxima en 12 meses (N/1/2/3/4/C/D) | F38: PN pag.1 > Tendencia > Total Moras Maximas (toda la fila)
C39: Tendencia de la mora 12m | F39: PN pag.1 > Tendencia > Saldo Deuda Total en Mora (en miles)
B41: PASO 4 · HABITO DE PAGO Y VECTORES (PN pags. 2-3)
C42: Estado de obligaciones vigentes | F42: PN pags.1-2 > Habito Pago Abiertas/Vigentes > Estado
C43: ¿Cuantas cuentas activas con MAS de 1 año tiene? (anti-suplantacion) | F43: PN pags.1-2 > Habito Abiertas: cuente cuentas AHO/AHD/CTE con fecha de apertura mayor a 12 meses
C44: Fecha de apertura de la cuenta de desembolso (DD/MM/AAAA) | F44: PN pags.1-2 > Habito: cuenta (AHO/CTE/BILLETERA) que el cliente puso en Digiventure
...

Sheet Flujo credito
B1: ANALISIS FINANCIERO PAGO DE CREDITOS
B2: Asalariado / Independiente
B3: AMARILLO = usted digita· GRIS = calculo automatico - no tocar.
B5: Solicitante | C5: {=+'Plan de pagos'!M5:N5} -> 0 | D5: 0
B6: C.C No. | C6: {=+'Plan de pagos'!M6:N6} -> 0 | D6: 0
B8: Estado de Ingresos y Resultados | D8: Valor | E8: % Partc
C9: Ingreso Reportado cliente | D9: =+'Captura información'!D62 -> 0
C10: QUANTO ingreso medio | D10: =+'Captura información'!D60 -> 0
B11: Entradas Mensuales | C11: Ingresos Brutos (salario, pensión, contratos) | D11: =IF(Reglas!$B$21="Declarado",D9,IF(Reglas!$B$21="QUANTO",D10,MIN(D9,D10))) -> 0 | E11: =IFERROR(+D11/D16,"")
C12: Comisiones, Rodamiento, Bonificaciones | D12: 0 | E12: =IFERROR(+D12/D16,"")
C13: Arriendos | D13: 0 | E13: =IFERROR(+D13/D16,"")
C14: Rendimientos Financieros | D14: 0 | E14: =IFERROR(+D14/D16,"")
C15: Otros ingresos | D15: 0 | E15: =IFERROR(+D15/D16,"")
C16: TOTAL INGRESOS | D16: =SUM(D11:D15) -> 0 | E16: =SUM(E11:E15) -> 0
C17: Descuentos de Ley | D17: =+D16*0.08 -> 0 | E17: =IFERROR(+D17/D16,"")
C18: TOTAL INGRESOS NETOS | D18: =D16-D17 -> 0
B20: Salidas Mensuales | C20: Gastos de sostenimiento | D20: =D18*Reglas!$B$15 -> 0 | E20: =IFERROR(+D20/D28,"")
C21: Arrendamientos | D21: 0 | E21: =IFERROR(+D21/D28,"")
C22: Manutención hijos (10% salario c/u) | D22: ='Captura información'!D66*(D18*Reglas!$B$19) -> 0 | E22: =IFERROR(+D22/D28,"")
C23: TOTAL Valor Cuota del reporte sin TDC (Datacredito) | D23: ='Captura información'!D32 -> 0 | E23: 0
C24: Cuotas tarjetas de credito (TDC) | D24: =+'Captura información'!D34 -> 0 | E24: =IFERROR(+D24/D28,"")
C25: TOTAL Valor Cuota Ajustada Factor Nano | D25: =('Captura información'!D32-'Captura información'!D33)+'Captura información'!D33*Reglas!$B$14 -> 0 | E25: =IFERROR(+D25/D28,"")
C26: Cuotas deudas particulares | D26: 0 | E26: =IFERROR(+D26/D28,"")
C27: Otros Gastos | D27: 0 | E27: =IFERROR(+D27/D28,"")
C28: TOTAL GASTOS | D28: =SUM(D20:D22)+ SUM(D24:D27) -> 0 | E28: =SUM(E20:E27) -> 0
B30: Indicadores de análisis
C31: Monto del crédito Solicitado | E31: =+'Plan de pagos'!P13 -> 0
B32: Información | C32: Monto del crédito Aprobado | E32: =+'Plan de pagos'!P14 -> 0
B33: del crédito | C33: Plazo | E33: {=+'Plan de pagos'!F8:H8} -> 2 | F33: 0 | G33: 0
C34: Tasa de interés efectiva anual | E34: =+'Plan de pagos'!J6 -> 0.2426
C35: Tasa de interés efectiva mensual | E35: {=+'Plan de pagos'!F7:H7} -> 0.018265303 | F35: 0 | G35: 0
C36: Dinero disponible del solicitante una vez deducido sus gastos actuales | E36: =+D18-D28 -> 0
C37: Cuota Finalco mensual a pagar | E37: =+'Plan de pagos'!P19 -> 15469.209
C38: Dinero disponible una vez pagado credito Finalco | E38: =+E36-E37 -> -15469.209
C39: Colchon de imprevistos | E39: =D18*Reglas!$B$17 -> 0
C40: Relación de la cuota vs el dinero disponible. | E40: =IFERROR(+E37/E36,"")
C41: Nuevo crédito aprobado vs Patrimonio | E41: 0
B42: Indicadores | C42: Total cuotas actuales vs ingresos neto | E42: =IFERROR((+D25+D24+D26)/D18,"")
C43: Relación cuota vs ingresos (Cuota mensual finalco / Ingresos Netos) | E43: =IFERROR(E37/D18,"")
C44: Disponible (vision estricta, cuota 100%) | E44: =+D18-D20-D21-D22-D26-D27-'Captura información'!D32-D24-E37 -> -15469.209
...

Sheet Motor de Decision
B2: FINALCO · MOTOR DE DECISION NANOCREDITO FINAMIGO
B3: Si la pestaña Captura Experian esta bien diligenciada, aqui ya aparece la respuesta definitiva. Solo ajuste manualmente si discrepa. Las desviaciones se resaltan en rojo.
B5: 1 · DATOS DE LA SOLICITUD
C6: Nombre del solicitante | D6: ='Flujo credito'!C5 -> 0
C7: Cedula | D7: ='Flujo credito'!C6 -> 0
C8: Nombre del analista de credito | D8: Valeria Bohorquez
C9: Tipo de credito | D9: ='Captura información'!D6 -> Renovacion
C10: Fecha del analisis (DD/MM/AAAA) | D10: =TODAY() -> 46218
C11: Destino del credito | D11: ='Plan de pagos'!M7 -> 0
C12: Monto solicitado | D12: ='Plan de pagos'!P13 -> 0
B14: 2 · INDICADORES COMPLEMENTARIOS (referencia · NO rechazan solos)
C15: Puntaje en centrales de riesgo | D15: ='Captura información'!D59 -> 0 | E15: =IF(NOT(ISNUMBER('Captura información'!D59)),"Sin dato",IF('Captura información'!D59>=700,"VERDE - historial sano",IF('Captura información'!D59>=500,"AMARILLO - revisar causa","ROJO - revisar a fondo"))) -> Sin dato
C16: Puntaje Begini (voluntad de pago) | D16: ='Captura información'!D63 -> 0 | E16: =IFERROR(CHOOSE('Captura información'!D63+1,"No contesto","Riesgo mas alto","Riesgo muy alto","Riesgo alto","Riesgo medio","Riesgo bajo","Riesgo muy bajo","Riesgo mas bajo","No termino"),"") -> No contesto
B18: 3 · RECHAZO TECNICO (duros = rechazo) y ALERTAS (preguntas SI/NO)
B19: 1 | C19: ¿El documento NO esta vigente (fallecido/cancelado/suspendido)? | D19: =IF('Captura información'!D7<>"Vigente","SI","NO") -> NO | F19: Captura: Estado del Documento
B20: 2 | C20: ¿La consulta es Tipo 5, 6 o 7 (no valida / apellido no coincide)? | D20: =IF('Captura información'!D8>=5,"SI","NO") -> NO | F20: Captura: Tipo de respuesta
B21: 3 | C21: ¿Castigada/dudoso vigente con saldo sobre el umbral? (bajo el umbral continua con tope $250K) | D21: =IF(OR(E21="SI",'Captura información'!$H$21="SI"),"SI","NO") -> NO | E21: NO | F21: Pre-filtro Captura: castigada/dudoso niega solo si saldo > Reglas B23; menor cuantia continua con tope Reglas B46
B22: 4 | C22: ¿Mora evidente superior? (>$400K o 2+ oblig. mora 60+, sin excepciones) | D22: =IF('Captura información'!$H$22="SI","SI","NO") -> NO | F22: Pre-filtro Captura: mora evidente (excepciones: mora unica / renovacion / mora <= 60 dias bajo el umbral)
B23: 5 | C23: ¿Tiene cobro juridico o prejudicial activo? | D23: NO | F23: Experian: Adjetivo-fecha (Cobro Juridico)
B24: 6 | C24: ¿Hay alerta de suplantacion o robo de cedula? | D24: NO | F24: Experian: Alertas/Desacuerdos (Suplantacion) o novedad biometria Digiventure
B25: ! | C25: ALERTA: ¿Alcanzo el tope de endeudamiento microcredito (Dec.919/2008)? | D25: NO | F25: Experian: seccion Alertas
B26: ! | C26: ALERTA: ¿Hay informacion judicial negativa (p.ej. deudor alimentario)? | D26: NO | F26: Experian: Comentarios/Desacuerdos
B27: ! | C27: ALERTA: ¿La capacidad de pago es insuficiente? (automatico) | D27: =IF('Flujo credito'!D52="NO","SI","NO") -> NO | F27: Automatico desde Flujo Empleado
B28: ! | C28: ALERTA: ¿Tiene demasiadas consultas (posible sobreendeudamiento)? | D28: =IF('Captura información'!D37>Reglas!$B$25,"SI","NO") -> NO | F28: Captura: consultas de entidades 6m (ya excluye CIUDADANO y LOTE)
C29: RESULTADO RECHAZO TECNICO | D29: =IF(OR(D19="SI",D20="SI",D21="SI",D22="SI",D23="SI",D24="SI"),"RECHAZO AUTOMATICO (rechazo tecnico duro)",IF(OR(OR(D25="SI",D26="SI",AND(D27="SI",Reglas!$B$20="COMITE")),D28="SI",D27="SI"),"HAY ALERTAS - revisar abajo","Primer filtro SUPERADO: continue con el puntaje")) -> Primer filtro SUPERADO: continue con el puntaje
B31: 4 · PUNTAJE POR EJES (resultado automatico · ajuste manual opcional)
C32: EJE CAPACIDAD (peso 30, editable en Reglas)
C33: Componente (pregunta) | D33: Resultado automatico | E33: Ajuste manual (opcional) | F33: Pts | G33: Max
C34: Uso del cupo: ¿que % del cupo total tiene ya usado? (Saldo/Cupo) | D34: =IF(ISNUMBER('Captura información'!D31),IF('Captura información'!D31<0.5,"Bajo: usa menos del 50% del cupo",IF('Captura información'!D31<0.8,"Medio: usa 50-80% del cupo",IF('Captura información'!D31<0.9,"Alto: usa 80-90% del cupo","Muy alto: usa mas del 90% del cupo"))),"") | F34: =IFERROR(VLOOKUP(IF(E34<>"",E34,D34),Listas!$A$2:$B$5,2,0),"") | G34: 10
C35: Holgura: la cuota nueva Finalco ¿que tan grande es frente a lo que ya paga al dia? | D35: =IF(ISNUMBER('Flujo credito'!E49),IF('Flujo credito'!E49<=0.2,"Comoda: cuota nueva <= 20% de lo que ya paga",IF('Flujo credito'!E49<=0.35,"Aceptable: 20-35%",IF('Flujo credito'!E49<=0.5,"Ajustada: 35-50%","Riesgosa: mas de 50% o hay mora"))),"") -> Comoda: cuota nueva <= 20% de lo que ya paga | F35: =IFERROR(VLOOKUP(IF(E35<>"",E35,D35),Listas!$A$7:$B$10,2,0),"") -> 10 | G35: 10
C36: Mora hoy: ¿cuanto debe en mora en este momento? (saldo en mora total) | D36: =IF(ISNUMBER('Captura información'!D13),IF('Captura información'!D13<=0,"Sano: $0 en mora",IF('Captura información'!D13<=100000,"Leve: $1 a $100.000",IF('Captura información'!D13<=500000,"Medio: $100.000 a $500.000","Grave: mas de $500.000"))),"") -> Sano: $0 en mora | F36: =IFERROR(VLOOKUP(IF(E36<>"",E36,D36),Listas!$A$12:$B$15,2,0),"") -> 6 | G36: 6
C37: Carga: ¿cuantos creditos vigentes tiene al tiempo? | D37: =IF(ISNUMBER('Captura información'!D9),IF('Captura información'!D9<=5,"1 a 5 creditos",IF('Captura información'!D9<=8,"6 a 8 creditos",IF('Captura información'!D9<=12,"9 a 12 creditos","Mas de 12 creditos"))),"") -> 1 a 5 creditos | F37: =IFERROR(VLOOKUP(IF(E37<>"",E37,D37),Listas!$A$17:$B$20,2,0),"") -> 5 | G37: 5
C38: Tarjetas de credito (TDC): ¿que % del cupo de sus tarjetas usa? | D38: =IF('Captura información'!D35="","Sin tarjetas de credito",IF('Captura información'!D35<0.3,"TDC bajo: usa menos del 30% del cupo",IF('Captura información'!D35<0.6,"TDC medio: 30-60%",IF('Captura información'!D35<0.9,"TDC alto: 60-90%","TDC al tope: mas del 90% (sin opciones)")))) -> Sin tarjetas de credito | F38: =IFERROR(VLOOKUP(IF(E38<>"",E38,D38),Listas!$A$129:$B$133,2,0),"") -> 3 | G38: 5
C39: Subtotal CAPACIDAD | F39: =IFERROR(SUM(F34:F38),0) -> 24 | G39: =SUM(G34:G38) -> 36
C40: EJE COMPORTAMIENTO (peso 30, editable en Reglas)
C41: Componente (pregunta) | D41: Resultado automatico | E41: Ajuste manual (opcional) | F41: Pts | G41: Max
C42: Comportamiento reciente: peor mora del vector en los ULTIMOS 6 MESES | D42: =IF('Captura información'!D47="N","Excelente: todo N (sin mora)",IF('Captura información'!D47="1","Bueno: maximo un 1 (30 dias) aislado",IF('Captura información'!D47="2","Regular: dos 1 o un 2 (60 dias)",IF(OR('Captura información'!D47="3",'Captura información'!D47="4"),"Malo: un 3 o 4 (90-120 dias)",IF(OR('Captura información'!D47="C",'Captura información'!D47="D"),"Critico: aparece D (dudoso) o C (castigada)",""))))) | F42: =IFERROR(VLOOKUP(IF(E42<>"",E42,D42),Listas!$A$22:$B$26,2,0),"") | G42: 15
C43: Estado actual: ¿como estan HOY sus obligaciones vigentes? | D43: ='Captura información'!D42 -> 0 | F43: =IFERROR(VLOOKUP(IF(E43<>"",E43,D43),Listas!$A$28:$B$31,2,0),"") | G43: 10
C44: Cierres pasados: ¿como cerro los creditos que ya termino? | D44: ='Captura información'!D46 -> 0 | F44: =IFERROR(VLOOKUP(IF(E44<>"",E44,D44),Listas!$A$33:$B$37,2,0),"") | G44: 8
C45: Puntualidad: ¿paga a tiempo? (dias de atraso / prepago) | D45: ='Captura información'!D49 -> 0 | F45: =IFERROR(VLOOKUP(IF(E45<>"",E45,D45),Listas!$A$39:$B$42,2,0),"") | G45: 6
...

Sheet Guia
A1: FINALCO · MOTOR DE DECISION FINAMIGO — GUIA DE USO (v3)
A2: Nanocredito $200.000 a $600.000 a maximo 2 meses
A4: ORDEN DE TRABAJO
A5: 1) PLAN DE PAGOS: ingrese monto, plazo y tasa. Obtiene la cuota mensual Finalco.
A6: 2) CAPTURA EXPERIAN: digite en AMARILLO lo que ve en los documentos (HC, Preselecta, Digiventure).
A7: Pase el mouse por cada celda amarilla para ver la AYUDA (definicion + ejemplo + donde mirar).
A8: Donde se pueda digite FECHAS y el Excel calcula edades/meses/anos solo (menos errores).
A9: 3) FLUJO EMPLEADO: complete ingresos y gastos. Indique cuanto de la cuota es nanocredito (pesa 50%),
A10: cuanto es de tarjetas, y cuantas personas a cargo. Revise la CAPACIDAD DE PAGO (SI/NO).
A11: 4) MOTOR DE DECISION: la decision, banda, monto y condiciones aparecen solas. Ajuste manual solo si discrepa.
A13: COMO LEER EL MOTOR (auto + ajuste manual)
A14: Cada componente muestra el 'Resultado automatico' (viene de Captura). Si una celda sale en ROJO, es una
... A49: - Calibrar pesos/cortes/banda con la mora real por banda cada trimestre.

Sheet Preguntas_Reto
Q1: SI
B2: Preguntas reto | Q2: NO
B3: Consideraciones, siempre se debe preguntar: - Fecha de expedición de CC -3 preguntas de datacrédito (minimo una afirmativa y una negativa)
B4: 0. Me puede indicar por favor la fecha y lugar de expedición de su CC (cliente debe responder rapidamente) | G4: 4. Me puede indicar por favor si ud. Tiene una cuenta activa de ahorros con el banco (Validar en datacrédito un banco con el que SI tenga producto). Rta Afirmativa
B7: 1. Me puede indicar por favor si ud. Tiene una cuenta activa de ______ (crédito o TDC) con el banco (Validar en datacrédito un banco con el que SI tenga producto). Rta Afirmativa | G7: 5. Me puede indicar por favor si ud. Tiene una cuenta activa con operador movil____ (validar en datacrédito con el que SI tenga producto). Rta afirmativa
B10: 2. Me puede indicar por favor si ud. Tiene una cuenta activa de______(crédito o TDC) con el banco (Validar en datacrédito un banco con el que NO tenga producto). Rta negativa | G10: 6. Me puede indicar por favor si ud. Tiene una cuenta activa con operador movil____ (validar en datacrédito con el que NO tenga producto). Rta negativa
B14: 3. Me puede indicar por favor si ud. Tiene una cuenta activa de ahorros con el banco (Validar en datacrédito un banco con el que NO tenga producto). Rta negativa

Sheet Evidencia Fotografica
B2: EVIDENCIA FOTOGRAFICA
B4: Solicitante | C4: =+'Plan de pagos'!M5 -> 0
B5: Doc de Identidad | C5: =+'Plan de pagos'!M6 -> 0
B6: Destino del crédito | C6: =+'Plan de pagos'!M7 -> 0
B8: EVIDENCIA FOTOGRAFICA DEL SITIO DE TRABAJO Y DEL CLIENTE
B52: MAPA DE UBICACIÓN DEL CLIENTE

Sheet Simulador
A3: Plan de pagos: Carta de bienvenida
B5: Cuota | C5: Fecha de vencimiento | F5: Saldo capital | I5: Abono capital | K5: Intereses | L5: Vida Deudores | M5: Fianza | N5: Cuota | O5: TOTAL
B6: 0 | F6: {=+'Plan de pagos'!F18:H18} -> 30000 | G6: 0 | H6: 0
B7: =+'Plan de pagos'!B19 -> 1 | C7: =+'Plan de pagos'!C19 -> 14 | D7: =+'Plan de pagos'!D19 -> Feb | E7: =+'Plan de pagos'!E19 -> 2026 | F7: {=+'Plan de pagos'!F19:H19} -> 15135.75 | G7: 0 | H7: 0 | I7: {=+'Plan de pagos'!J19:K19} -> 14864.25 | J7: 0 | K7: =+'Plan de pagos'!L19 -> 547.9591 | L7: =+'Plan de pagos'!M19 -> 57 | M7: =+'Plan de pagos'!N19 -> 0 | N7: =+'Plan de pagos'!O19 -> 15412.209 | O7: =+'Plan de pagos'!P19 -> 15469.209
B8: =+'Plan de pagos'!B20 -> 2 | C8: =+'Plan de pagos'!C20 -> 14 | D8: =+'Plan de pagos'!D20 -> Mar | E8: =+'Plan de pagos'!E20 -> 2026 | F8: {=+'Plan de pagos'!F20:H20} -> -1.8189894e-12 | G8: 0 | H8: 0 | I8: {=+'Plan de pagos'!J20:K20} -> 15135.75 | J8: 0 | K8: =+'Plan de pagos'!L20 -> 276.45907 | L8: =+'Plan de pagos'!M20 -> 57 | M8: =+'Plan de pagos'!N20 -> 0 | N8: =+'Plan de pagos'!O20 -> 15412.209 | O8: =+'Plan de pagos'!P20 -> 15469.209
I9: {=+'Plan de pagos'!J21:K21} -> 30000 | J9: 0 | K9: =+'Plan de pagos'!L21 -> 824.41817 | L9: =+'Plan de pagos'!M21 -> 114 | M9: =+'Plan de pagos'!N21 -> 0 | N9: =+'Plan de pagos'!O21 -> 30824.418 | O9: =+'Plan de pagos'!P21 -> 30938.418
A13: Simulador:
A15: Valor solicitado | B15: =+'Plan de pagos'!P14 -> 0
A16: Interés | B16: =+K9 -> 824.41817
A17: Seguro vida | B17: =+L9 -> 114
A18: Fianza + IVA | B18: =+M9 -> 0
A19: Tecnología + IVA | B19: =(+B15*3%)+7800 -> 7800
A20: Administración | B20: 30000
A21: Descuento (por inclusión financiera) | B21: =-B19 -> -7800
A22: Total a pagar | B22: =SUM(B15:B21) -> 30938.418

Sheet Guion
B2: GUIÓN PRE-APROBADO FINAMIGO
B4: Saludo | C4: Buen día sr(a)________________, Habla con __________ del aréa de crédito de Finalco SAS. ¿Como se encuentra el día de hoy? Rta. Positiva: Me alegra Rta negativa: Entiendo El motivo de mi llamada, se debe a que ud. Solicito un préstamo Finamigo, el cual se encuentra en estado pre-aprobado
B6: Preguntas Reto | C6: , por lo que requerimos realizar unas preguntas de seguridad, para validar su identidad. Quisiera conocer si ud. dispone de unos minutos para atender la llamada, de salir positivas las respuestas procedemos a brindar las condiciones del crédito y firmar el pagaré digital.
C7: Rta. Positiva: De acuerdo (realizar Preguntas reto)
C8: Rta negativa: Entiendo, en que horario puedo llamarlo nuevamente. Entonces me contactare en ese horario. Recuerde que hablo con ____________ de Finalco SAS. Que tenga buen resto de día.
B10: condiciones de crédito en caso de que cambie el valor de la solicitud | C10: Cliente pasa el filtro, debe responder 3/4: | E10: Cliente NO pasa el filtro, debe responder 3/4:
C11: Perfecto sr(a)________ las respuestas fueron correctas, por lo cual procedo a indicarle las condiciones del crédito: Monto:________ Plazo:_________ Valor cuota:______________ Fecha de pago:___________ | E11: Sr(a)________, lamento informarle que fallamos en las respuestas de seguridad, por lo cual el sistema rechaza automaticamente su solicitud de crédito. Recuerde que hablo con ____________ de Finalco SAS. Que tenga buen resto de día.
C12: ¿Tiene alguna duda con la información brindada?
B14: Firma Pagaré | C14: Rta. Positiva: Le confirmo el proceso para firmar el pagaré y aprobar la solicitud. Rta negativa: Resolver inquietud
C16: A su correo electronico le va a llegar en unos minutos un email para la firma de pagaré digital. A su whatsapp le voy a enviar el link del video donde explica como hacer el proceso, el cual es muy sencillo. Inmediatamente quede firmado el documento, a ud. Le llega una copia a su correo. | E16: https://finalco.com.co/firma_pagare/
B17: Confirmar la cuenta bancaria… Preguntar si tiene nequi o Bancolombia La cuenta si o si debe estar a nombre del cliente
B18: Despedida | C18: Recuerde que una vez quede aprobado el préstamo le llegará un correo informandolo y cuando se realice el desembolso, le llegara una carta de bienvenida con la información del crédito y los canales de pago.
C19: Le recuerdo tambien que este crédito es diferente al actual por lo que son dos cuotas apartes
C20: Muchas gracias por atender mi llamada, recuerde que hablo con ____________ de Finalco SAS. Que tenga buen resto de día.

Sheet Referenciación
B2: FORMATO DE REFERENCIACION
B4: Asesor
B6: Observaciones del Crédito:
B9: Certificación Laboral
B11: Nombre: | E11: Teléfono
B13: Cargo: | E13: Observaciones:
B15: Referencia 2.
B17: Nombre | E17: Teléfono
P18: propia
B19: Parentesco | P19: Arrendada
P20: Familiar
B21: Hace cuanto conoce al señor (a)
A22: En qué lugar vive:
F23: hace cuánto tiempo:
B25: Cuál es la actividad principal: | G25: Empresa (si es empleado)
B27: Cuantos hijos tiene | G27: de que edades
B29: Vive en casa:
B31: Qué referencia me podría dar del señor (a):
B33: Referencia 1.
B35: Nombre | E35: Teléfono
B37: Parentesco
B39: Hace cuanto conoce al señor (a)
A40: En qué lugar vive:
F41: hace cuánto tiempo:
B43: Cuál es la actividad principal: | G43: Empresa (si es empleado)
B45: Cuantos hijos tiene | G45: de que edades
B47: Vive en casa:
B49: Qué referencia me podría dar del señor (a):

Sheet Preguntas reto
B2: GUION PREGUNTAS RETO FINAMIGO
B4: SALUDO | C4: Buen día sr(a)________________, Habla con __________ del área de crédito de Finalco SAS. ¿Como se encuentra el día de hoy? Rta. Positiva: Me alegra Rta negativa: Entiendo
C6: El motivo de mi llamada se debe a que usted solicito un préstamo Finamigo, y para el desembolso se hace necesario validar su identidad.
C8: Le informamos que este procedimiento no tomara mucho tiempo y será muy breve.
C9: Le recomendamos igualmente preste atención a las preguntas y a las respuestas ya que de este proceso depende la aprobación final del crédito. En caso de que las preguntas quede mal contestadas, el área de gestión de riesgo se comunicara posteriormente con usted.
C12: 1. Me puede confirmar la fecha de expedición de su documento.
C13: Rta: debe validar directamente en la cedula
C14: 2. ¿Con que banco usted tiene cuenta de ahorro?
B15: PREGUNTAS | C15: A.) Caja social.
C16: B.) Bogota.
C17: C.) Pichincha.
C18: D.) Ninguna de las anteriores.
C19: Rta:
C20: 3. ¿Con que banco tiene usted tarjeta de credito?
C21: A.) Colpatria.
C22: B.) Juriscop.
C23: C.) Bancolombia.
C24: D.) Ninguna de las anteriores.
C25: Rta:
C26: 4.) Usted conoce o ha tenido contacto con alguna de las siguientes direcciones.?
C27: Direccion 1:
... C30: Nota Finalco:
B34: Video descarga NEQUI cetificado | C34: https://www.youtube.com/watch?v=aYt_zxMKKwM&t=5s
B35: Video descarga Daviplata cetificado | C35: https://www.youtube.com/watch?v=rIN4zjCPmq8

Sheet Reglas
A1: FINALCO . REGLAS Y PARAMETROS (editar SOLO aqui para calibrar)
A3: PESOS DE LOS EJES (normaliza a 100 aunque no sumen 100)
A4: Peso eje CAPACIDAD | B4: 30
A5: Peso eje COMPORTAMIENTO | B5: 30
A6: Peso eje FLUJO | B6: 20
A7: Peso eje ENTORNO | B7: 8
A8: CORTES DE BANDA (puntaje >=)
A9: Banda A - Aprobar $400-600K | B9: 80 | C9: Calibrar con mora real por banda cada trimestre
A10: Banda B - Aprobar $300-400K | B10: 65
A11: Banda C - Aprobar entrada $200K | B11: 50
A12: Banda C- - Revision Comite | B12: 40
A13: CAPACIDAD DE PAGO Y FACTORES NANO
A14: Factor cuota nanocredito (se auto-liquida) | B14: 0.5 | C14: Cuota nano pesa 50%; credito normal 100%
A15: Gasto de sostenimiento (% netos) | B15: 0.35
A16: Descuentos de ley (%) | B16: 0.08
A17: Colchon de imprevistos (% netos) | B17: 0.08
A18: Limite cuota / ingreso neto | B18: 0.3
A19: Manutencion por persona a cargo (% netos) | B19: 0.1 | C19: Se multiplica por # personas a cargo (Flujo Empleado)
A20: Capacidad insuficiente => | B20: CONDICION | C20: CONDICION (Aprobado Condic.) o COMITE (Revision). Ver Guia
A21: Base de ingreso para capacidad | B21: Conservador | C21: Conservador=MIN(declarado,QUANTO) . Declarado . QUANTO. Para rotadores probados puede usar Declarado.
A22: UMBRALES DE RECHAZO TECNICO
A23: Umbral mora evidente / castigada y excepcion renovacion ($) | B23: 400000
A24: Mora vigente >= (dias) | B24: 60
A25: Alerta si total consultas (6m) supera | B25: 10 | C25: Muchas consultas = posible sobreendeudamiento (excluir CIUDADANO y CONSULTAS LOTE)
A26: COSTOS DEL CREDITO (default produccion DG . CONFIRMAR Finalco)
A27: Tasa E.A. (referencia; el calculo real esta en Plan de pagos) | B27: 0.2426 | C27: DG=24.26% . v11=29.68% (PENDIENTE confirmar)
A28: Administracion (fijo $) | B28: 30000
A29: Tecnologia (% del monto) | B29: 0.03 | C29: +7.800 fijo
A30: LISTA DE ANALISTAS DE CREDITO (firma)
A31: Luna Munoz
A32: Angelica Barajas
A33: Valeria Bohorquez
A34: Dayana Garibello
A35: Felipe Bohorquez
A36: Fredy Pito
A37: Jhon Enriquez
A38: Peso Comportamiento (perfil NUEVO) | B38: 12 | C38: En Ruta Nuevo el comportamiento se mide con telco (señal mas debil); por eso pesa menos (12 vs 30).
A39: MENSAJES TIPO COMITE (checkbox -> parrafo automatico)
A40: 1. Validar identidad con preguntas reto
A41: 2. Solicitar documentacion soporte para validar direccion, telefono o cuenta de ahorros
...

Sheet Listas
A1: Opcion | B1: Puntos
A2: Bajo: usa menos del 50% del cupo | B2: 10
A3: Medio: usa 50-80% del cupo | B3: 8
A4: Alto: usa 80-90% del cupo | B4: 5
A5: Muy alto: usa mas del 90% del cupo | B5: 2
A7: Comoda: cuota nueva <= 20% de lo que ya paga | B7: 10
A8: Aceptable: 20-35% | B8: 7
A9: Ajustada: 35-50% | B9: 4
A10: Riesgosa: mas de 50% o hay mora | B10: 0
A12: Sano: $0 en mora | B12: 6
A13: Leve: $1 a $100.000 | B13: 3
A14: Medio: $100.000 a $500.000 | B14: 1
A15: Grave: mas de $500.000 | B15: 0
... A108: Mas de 10 entidades | B108: 1
A110: Begini | B110: Ajuste
A111: 0 | B111: 0
A112: 1 | B112: -6
A113: 2 | B113: -4
A114: 3 | B114: -2
A115: 4 | B115: 0
A116: 5 | B116: 2
A117: 6 | B117: 3
A118: 7 | B118: 4
A119: 8 | B119: 0
A121: Cotizante activo (contributivo) | B121: 3
A122: Regimen de excepcion / especial | B122: 3
A123: Independiente con PILA / Subsidiado activo | B123: 0
A124: Retirado, suspendido o sin afiliacion | B124: -4
A126: Si - vehiculo/patrimonio a su nombre verificado | B126: 2
A127: No / no verificable | B127: 0
A129: Sin tarjetas de credito | B129: 3
A130: TDC bajo: usa menos del 30% del cupo | B130: 5
A131: TDC medio: 30-60% | B131: 3
A132: TDC alto: 60-90% | B132: 1
A133: TDC al tope: mas del 90% (sin opciones) | B133: 0
A135: Al dia (sin atrasos) | B135: 8
... A138: Sin telco | B138: 4

Sheet Calculo_Score
B2: COMO SE CALCULA EL PUNTAJE · Pesos de los ejes
B3: El puntaje es un PROMEDIO PONDERADO: como el promedio del semestre donde cada materia vale distintos creditos.
B5: LA IDEA EN UNA FRASE
B6: Cada eje se califica sobre SU PROPIO MAXIMO (saca un %). Ese % se multiplica por su PESO, se suman todos y se divide por la SUMA DE LOS PESOS. Por eso el resultado siempre queda entre 0 y 100, aunque los pesos no sumen 100.
B8: LOS 3 PASOS
B9: 1) Saca el % de cada eje = puntos obtenidos / puntos maximos del eje.
B10: 2) Pondera = ese % x el peso del eje.
B11: 3) Normaliza = suma todo / (suma de los pesos) x 100.
B13: FORMULA: | C13: Puntaje = [ Σ (puntos_eje / maximo_eje x peso_eje) ] / (suma de pesos) x 100
B15: EJEMPLO SIMPLE (2 ejes, pesos que NO suman 100)
B16: Eje | C16: Puntos | D16: Maximo | E16: % del eje | F16: Peso | G16: Aporte (% x peso)
B17: Comportamiento | C17: 24 | D17: 30 | E17: 0.8 | F17: 30 | G17: 2400
B18: Flujo | C18: 10 | D18: 20 | E18: 0.5 | F18: 20 | G18: 1000
B19: SUMA | F19: 50 | G19: 3400
B20: Puntaje = 3400 / 50 = 68 -> 68 / 100
B21: Los pesos sumaban 50 (no 100) y aun asi la nota quedo en escala 0-100. Eso es la NORMALIZACION.
B23: EL TRUCO: si pones un peso en 0, ese eje desaparece solo
B24: Con Flujo = 0: Puntaje = (80% x 30) / 30 = 80. El motor reparte solo entre los ejes que quedan, sin tocar ninguna formula. Por eso puedes recalibrar los pesos en la hoja Reglas cuando quieras.
B26: TUS 4 EJES REALES (ejemplo caso Villa)
B27: Pesos por defecto: Capacidad 30 · Comportamiento 30 · Flujo 20 · Entorno 8 (suman 88, y no importa).
B28: Eje | C28: Puntos | D28: Maximo | E28: % del eje | F28: Peso | G28: Aporte (% x peso)
B29: Capacidad | C29: 23 | D29: 31 | E29: 0.742 | F29: 30 | G29: 22.3
B30: Comportamiento | C30: 53 | D30: 55 | E30: 0.964 | F30: 30 | G30: 28.9
B31: Flujo | C31: 7 | D31: 20 | E31: 0.35 | F31: 20 | G31: 7
B32: Entorno | C32: 20 | D32: 22 | E32: 0.909 | F32: 8 | G32: 7.3
B33: SUMA | F33: 88 | G33: 65.5
B34: Puntaje base = 65.5 / 88 x 100 = 74.4 (luego se suman Begini, ADRES, etc.)
B36: EN POCAS PALABRAS
B37: No importa que los pesos sumen 100. Lo que importa es la PROPORCION entre ellos (Comportamiento pesa igual que Capacidad, Flujo un poco menos, Entorno poco). La division final por la suma de pesos vuelve todo a una nota de 0 a 100.
